Workbook

Sheet PRAZO_GRADE
Z2: ↓ | AA2: ↓ | AB2: ↓
B3: V. 4.0 08/04 | C3: 46120 | R3: PREENCHER PARA IGUALAR AO CONTA CRÉDITO | T3: PREENCHER PARA ALTERAR GRADE | X3: PREENCHER PARA ALTERAR PRAZO
L4: ↓ | T4: ATUAL | W4: PROPOSTO | X4: ATUAL | Y4: PROPOSTO | AC4: ↓ | AD4: ↓ | AE4: ↓
B5: PERÍODO NEGOCIAÇÃO INÍCIO | C5: PERÍODO NEGOCIAÇÃO FIM | D5: MARCA SOLICITANTE | E5: FILIAL | F5: GV | G5: SUPERVISOR | H5: ORGANIZAÇÃO DE VENDAS | I5: CÓDIGO SAP CLIENTE | J5: CÓDIGO PFAT CLIENTE | K5: RAZÃO SOCIAL | L5: CNPJ | M5: CÓD. REDE | N5: NOME REDE | O5: CÓD. BAND | P5: NOME BANDEIRA | Q5: AÇÃO PARA REDE OU CLIENTE? | R5: CONTA CRÉDITO | S5: IGUALAR COM CONTA CRÉDITO? | T5: GRADE ATUAL | U5: MÍDIA | V5: DESC. FIN CLI/REDE | W5: GRADE PROPOSTA | X5: PRAZO ATUAL CLI / REDE | Y5: TIPO PARCELAMENTO / PRAZO PROPOSTO | Z5: MATERIAL BANDEIRA GMR GERAL | AA5: DESCRIÇÃO | AB5: CANAL DE FATURAMENTO (EPAN , PE OU OL) | AC5: MD TRIM | AD5: VOLUME PROPOSTO PARA O PERÍODO | AE5: OBS
B7: =TODAY() -> 46135 | C7: INDETERMINADO | D7: SANTA CRUZ | E7: =IFERROR(VLOOKUP($J7,'Base 1'!A:S,19,0),"-") -> - | F7: =IFERROR(VLOOKUP($J7,'Base 1'!$A:$N,14,0),"-") -> - | G7: =IFERROR(VLOOKUP($J7,'Base 1'!$A:$O,15,0),"-") -> - | H7: =IFERROR(VLOOKUP($J7,'Base 1'!$A:$T,20,0),"-") -> - | I7: =IFERROR(VLOOKUP($J7,'Base 1'!$A:$C,3,0),"-") -> - | K7: =IFERROR(VLOOKUP($J7,'Base 1'!$A:$E,5,0),"-") -> - | L7: =IFERROR(VLOOKUP($J7,'Base 1'!$A:$B,2,0),"-") -> - | M7: =IFERROR(VLOOKUP($J7,'Base 1'!$A:$Q,17,0),"-") -> - | N7: =IFERROR(VLOOKUP($J7,'Base 1'!$A:$R,18,0),"-") -> - | O7: =IFERROR(VLOOKUP($J7,'Base 1'!$A:$F,6,0),"-") -> - | P7: =IFERROR(VLOOKUP($J7,'Base 1'!$A:$G,7,0),"-") -> - | R7: =IFERROR(VLOOKUP(J7,'Base 1'!$A:$L,12,0),"-") -> - | T7: =IFERROR(VLOOKUP(J7,'Base 1'!$A:$J,10,0),"-") -> - | X7: =IFERROR(VLOOKUP(J7,'Base 1'!$A:$I,9,0),"-") -> - | AC7: =IFERROR(VLOOKUP($J7,'Base 1'!$A:$Q,16,0),"-") -> -
B8: =TODAY() -> 46135 | C8: INDETERMINADO | D8: SANTA CRUZ | E8: =IFERROR(VLOOKUP($J8,'Base 1'!A:S,19,0),"-") -> - | F8: =IFERROR(VLOOKUP($J8,'Base 1'!$A:$N,14,0),"-") -> - | G8: =IFERROR(VLOOKUP($J8,'Base 1'!$A:$O,15,0),"-") -> - | H8: =IFERROR(VLOOKUP($J8,'Base 1'!$A:$T,20,0),"-") -> - | I8: =IFERROR(VLOOKUP($J8,'Base 1'!$A:$C,3,0),"-") -> - | K8: =IFERROR(VLOOKUP($J8,'Base 1'!$A:$E,5,0),"-") -> - | L8: =IFERROR(VLOOKUP($J8,'Base 1'!$A:$B,2,0),"-") -> - | M8: =IFERROR(VLOOKUP($J8,'Base 1'!$A:$Q,17,0),"-") -> - | N8: =IFERROR(VLOOKUP($J8,'Base 1'!$A:$R,18,0),"-") -> - | O8: =IFERROR(VLOOKUP($J8,'Base 1'!$A:$F,6,0),"-") -> - | P8: =IFERROR(VLOOKUP($J8,'Base 1'!$A:$G,7,0),"-") -> - | R8: =IFERROR(VLOOKUP(J8,'Base 1'!$A:$L,12,0),"-") -> - | T8: =IFERROR(VLOOKUP(J8,'Base 1'!$A:$J,10,0),"-") -> - | X8: =IFERROR(VLOOKUP(J8,'Base 1'!$A:$I,9,0),"-") -> - | AC8: =IFERROR(VLOOKUP($J8,'Base 1'!$A:$Q,16,0),"-") -> -
B9: =TODAY() -> 46135 | C9: INDETERMINADO | D9: SANTA CRUZ | E9: =IFERROR(VLOOKUP($J9,'Base 1'!A:S,19,0),"-") -> - | F9: =IFERROR(VLOOKUP($J9,'Base 1'!$A:$N,14,0),"-") -> - | G9: =IFERROR(VLOOKUP($J9,'Base 1'!$A:$O,15,0),"-") -> - | H9: =IFERROR(VLOOKUP($J9,'Base 1'!$A:$T,20,0),"-") -> - | I9: =IFERROR(VLOOKUP($J9,'Base 1'!$A:$C,3,0),"-") -> - | K9: =IFERROR(VLOOKUP($J9,'Base 1'!$A:$E,5,0),"-") -> - | L9: =IFERROR(VLOOKUP($J9,'Base 1'!$A:$B,2,0),"-") -> - | M9: =IFERROR(VLOOKUP($J9,'Base 1'!$A:$Q,17,0),"-") -> - | N9: =IFERROR(VLOOKUP($J9,'Base 1'!$A:$R,18,0),"-") -> - | O9: =IFERROR(VLOOKUP($J9,'Base 1'!$A:$F,6,0),"-") -> - | P9: =IFERROR(VLOOKUP($J9,'Base 1'!$A:$G,7,0),"-") -> - | R9: =IFERROR(VLOOKUP(J9,'Base 1'!$A:$L,12,0),"-") -> - | T9: =IFERROR(VLOOKUP(J9,'Base 1'!$A:$J,10,0),"-") -> - | X9: =IFERROR(VLOOKUP(J9,'Base 1'!$A:$I,9,0),"-") -> - | AC9: =IFERROR(VLOOKUP($J9,'Base 1'!$A:$Q,16,0),"-") -> -
B10: =TODAY() -> 46135 | C10: INDETERMINADO | D10: SANTA CRUZ | E10: =IFERROR(VLOOKUP($J10,'Base 1'!A:S,19,0),"-") -> - | F10: =IFERROR(VLOOKUP($J10,'Base 1'!$A:$N,14,0),"-") -> - | G10: =IFERROR(VLOOKUP($J10,'Base 1'!$A:$O,15,0),"-") -> - | H10: =IFERROR(VLOOKUP($J10,'Base 1'!$A:$T,20,0),"-") -> - | I10: =IFERROR(VLOOKUP($J10,'Base 1'!$A:$C,3,0),"-") -> - | K10: =IFERROR(VLOOKUP($J10,'Base 1'!$A:$E,5,0),"-") -> - | L10: =IFERROR(VLOOKUP($J10,'Base 1'!$A:$B,2,0),"-") -> - | M10: =IFERROR(VLOOKUP($J10,'Base 1'!$A:$Q,17,0),"-") -> - | N10: =IFERROR(VLOOKUP($J10,'Base 1'!$A:$R,18,0),"-") -> - | O10: =IFERROR(VLOOKUP($J10,'Base 1'!$A:$F,6,0),"-") -> - | P10: =IFERROR(VLOOKUP($J10,'Base 1'!$A:$G,7,0),"-") -> - | R10: =IFERROR(VLOOKUP(J10,'Base 1'!$A:$L,12,0),"-") -> - | T10: =IFERROR(VLOOKUP(J10,'Base 1'!$A:$J,10,0),"-") -> - | X10: =IFERROR(VLOOKUP(J10,'Base 1'!$A:$I,9,0),"-") -> - | AC10: =IFERROR(VLOOKUP($J10,'Base 1'!$A:$Q,16,0),"-") -> -
B11: =TODAY() -> 46135 | C11: INDETERMINADO | D11: SANTA CRUZ | E11: =IFERROR(VLOOKUP($J11,'Base 1'!A:S,19,0),"-") -> - | F11: =IFERROR(VLOOKUP($J11,'Base 1'!$A:$N,14,0),"-") -> - | G11: =IFERROR(VLOOKUP($J11,'Base 1'!$A:$O,15,0),"-") -> - | H11: =IFERROR(VLOOKUP($J11,'Base 1'!$A:$T,20,0),"-") -> - | I11: =IFERROR(VLOOKUP($J11,'Base 1'!$A:$C,3,0),"-") -> - | K11: =IFERROR(VLOOKUP($J11,'Base 1'!$A:$E,5,0),"-") -> - | L11: =IFERROR(VLOOKUP($J11,'Base 1'!$A:$B,2,0),"-") -> - | M11: =IFERROR(VLOOKUP($J11,'Base 1'!$A:$Q,17,0),"-") -> - | N11: =IFERROR(VLOOKUP($J11,'Base 1'!$A:$R,18,0),"-") -> - | O11: =IFERROR(VLOOKUP($J11,'Base 1'!$A:$F,6,0),"-") -> - | P11: =IFERROR(VLOOKUP($J11,'Base 1'!$A:$G,7,0),"-") -> - | R11: =IFERROR(VLOOKUP(J11,'Base 1'!$A:$L,12,0),"-") -> - | T11: =IFERROR(VLOOKUP(J11,'Base 1'!$A:$J,10,0),"-") -> - | X11: =IFERROR(VLOOKUP(J11,'Base 1'!$A:$I,9,0),"-") -> - | AC11: =IFERROR(VLOOKUP($J11,'Base 1'!$A:$Q,16,0),"-") -> -
B12: =TODAY() -> 46135 | C12: INDETERMINADO | D12: SANTA CRUZ | E12: =IFERROR(VLOOKUP($J12,'Base 1'!A:S,19,0),"-") -> - | F12: =IFERROR(VLOOKUP($J12,'Base 1'!$A:$N,14,0),"-") -> - | G12: =IFERROR(VLOOKUP($J12,'Base 1'!$A:$O,15,0),"-") -> - | H12: =IFERROR(VLOOKUP($J12,'Base 1'!$A:$T,20,0),"-") -> - | I12: =IFERROR(VLOOKUP($J12,'Base 1'!$A:$C,3,0),"-") -> - | K12: =IFERROR(VLOOKUP($J12,'Base 1'!$A:$E,5,0),"-") -> - | L12: =IFERROR(VLOOKUP($J12,'Base 1'!$A:$B,2,0),"-") -> - | M12: =IFERROR(VLOOKUP($J12,'Base 1'!$A:$Q,17,0),"-") -> - | N12: =IFERROR(VLOOKUP($J12,'Base 1'!$A:$R,18,0),"-") -> - | O12: =IFERROR(VLOOKUP($J12,'Base 1'!$A:$F,6,0),"-") -> - | P12: =IFERROR(VLOOKUP($J12,'Base 1'!$A:$G,7,0),"-") -> - | R12: =IFERROR(VLOOKUP(J12,'Base 1'!$A:$L,12,0),"-") -> - | T12: =IFERROR(VLOOKUP(J12,'Base 1'!$A:$J,10,0),"-") -> - | X12: =IFERROR(VLOOKUP(J12,'Base 1'!$A:$I,9,0),"-") -> - | AC12: =IFERROR(VLOOKUP($J12,'Base 1'!$A:$Q,16,0),"-") -> -
B13: =TODAY() -> 46135 | C13: INDETERMINADO | D13: SANTA CRUZ | E13: =IFERROR(VLOOKUP($J13,'Base 1'!A:S,19,0),"-") -> - | F13: =IFERROR(VLOOKUP($J13,'Base 1'!$A:$N,14,0),"-") -> - | G13: =IFERROR(VLOOKUP($J13,'Base 1'!$A:$O,15,0),"-") -> - | H13: =IFERROR(VLOOKUP($J13,'Base 1'!$A:$T,20,0),"-") -> - | I13: =IFERROR(VLOOKUP($J13,'Base 1'!$A:$C,3,0),"-") -> - | K13: =IFERROR(VLOOKUP($J13,'Base 1'!$A:$E,5,0),"-") -> - | L13: =IFERROR(VLOOKUP($J13,'Base 1'!$A:$B,2,0),"-") -> - | M13: =IFERROR(VLOOKUP($J13,'Base 1'!$A:$Q,17,0),"-") -> - | N13: =IFERROR(VLOOKUP($J13,'Base 1'!$A:$R,18,0),"-") -> - | O13: =IFERROR(VLOOKUP($J13,'Base 1'!$A:$F,6,0),"-") -> - | P13: =IFERROR(VLOOKUP($J13,'Base 1'!$A:$G,7,0),"-") -> - | R13: =IFERROR(VLOOKUP(J13,'Base 1'!$A:$L,12,0),"-") -> - | T13: =IFERROR(VLOOKUP(J13,'Base 1'!$A:$J,10,0),"-") -> - | X13: =IFERROR(VLOOKUP(J13,'Base 1'!$A:$I,9,0),"-") -> - | AC13: =IFERROR(VLOOKUP($J13,'Base 1'!$A:$Q,16,0),"-") -> -
B14: =TODAY() -> 46135 | C14: INDETERMINADO | D14: SANTA CRUZ | E14: =IFERROR(VLOOKUP($J14,'Base 1'!A:S,19,0),"-") -> - | F14: =IFERROR(VLOOKUP($J14,'Base 1'!$A:$N,14,0),"-") -> - | G14: =IFERROR(VLOOKUP($J14,'Base 1'!$A:$O,15,0),"-") -> - | H14: =IFERROR(VLOOKUP($J14,'Base 1'!$A:$T,20,0),"-") -> - | I14: =IFERROR(VLOOKUP($J14,'Base 1'!$A:$C,3,0),"-") -> - | K14: =IFERROR(VLOOKUP($J14,'Base 1'!$A:$E,5,0),"-") -> - | L14: =IFERROR(VLOOKUP($J14,'Base 1'!$A:$B,2,0),"-") -> - | M14: =IFERROR(VLOOKUP($J14,'Base 1'!$A:$Q,17,0),"-") -> - | N14: =IFERROR(VLOOKUP($J14,'Base 1'!$A:$R,18,0),"-") -> - | O14: =IFERROR(VLOOKUP($J14,'Base 1'!$A:$F,6,0),"-") -> - | P14: =IFERROR(VLOOKUP($J14,'Base 1'!$A:$G,7,0),"-") -> - | R14: =IFERROR(VLOOKUP(J14,'Base 1'!$A:$L,12,0),"-") -> - | T14: =IFERROR(VLOOKUP(J14,'Base 1'!$A:$J,10,0),"-") -> - | X14: =IFERROR(VLOOKUP(J14,'Base 1'!$A:$I,9,0),"-") -> - | AC14: =IFERROR(VLOOKUP($J14,'Base 1'!$A:$Q,16,0),"-") -> -
B15: =TODAY() -> 46135 | C15: INDETERMINADO | D15: SANTA CRUZ | E15: =IFERROR(VLOOKUP($J15,'Base 1'!A:S,19,0),"-") -> - | F15: =IFERROR(VLOOKUP($J15,'Base 1'!$A:$N,14,0),"-") -> - | G15: =IFERROR(VLOOKUP($J15,'Base 1'!$A:$O,15,0),"-") -> - | H15: =IFERROR(VLOOKUP($J15,'Base 1'!$A:$T,20,0),"-") -> - | I15: =IFERROR(VLOOKUP($J15,'Base 1'!$A:$C,3,0),"-") -> - | K15: =IFERROR(VLOOKUP($J15,'Base 1'!$A:$E,5,0),"-") -> - | L15: =IFERROR(VLOOKUP($J15,'Base 1'!$A:$B,2,0),"-") -> - | M15: =IFERROR(VLOOKUP($J15,'Base 1'!$A:$Q,17,0),"-") -> - | N15: =IFERROR(VLOOKUP($J15,'Base 1'!$A:$R,18,0),"-") -> - | O15: =IFERROR(VLOOKUP($J15,'Base 1'!$A:$F,6,0),"-") -> - | P15: =IFERROR(VLOOKUP($J15,'Base 1'!$A:$G,7,0),"-") -> - | R15: =IFERROR(VLOOKUP(J15,'Base 1'!$A:$L,12,0),"-") -> - | T15: =IFERROR(VLOOKUP(J15,'Base 1'!$A:$J,10,0),"-") -> - | X15: =IFERROR(VLOOKUP(J15,'Base 1'!$A:$I,9,0),"-") -> - | AC15: =IFERROR(VLOOKUP($J15,'Base 1'!$A:$Q,16,0),"-") -> -
B16: =TODAY() -> 46135 | C16: INDETERMINADO | D16: SANTA CRUZ | E16: =IFERROR(VLOOKUP($J16,'Base 1'!A:S,19,0),"-") -> - | F16: =IFERROR(VLOOKUP($J16,'Base 1'!$A:$N,14,0),"-") -> - | G16: =IFERROR(VLOOKUP($J16,'Base 1'!$A:$O,15,0),"-") -> - | H16: =IFERROR(VLOOKUP($J16,'Base 1'!$A:$T,20,0),"-") -> - | I16: =IFERROR(VLOOKUP($J16,'Base 1'!$A:$C,3,0),"-") -> - | K16: =IFERROR(VLOOKUP($J16,'Base 1'!$A:$E,5,0),"-") -> - | L16: =IFERROR(VLOOKUP($J16,'Base 1'!$A:$B,2,0),"-") -> - | M16: =IFERROR(VLOOKUP($J16,'Base 1'!$A:$Q,17,0),"-") -> - | N16: =IFERROR(VLOOKUP($J16,'Base 1'!$A:$R,18,0),"-") -> - | O16: =IFERROR(VLOOKUP($J16,'Base 1'!$A:$F,6,0),"-") -> - | P16: =IFERROR(VLOOKUP($J16,'Base 1'!$A:$G,7,0),"-") -> - | R16: =IFERROR(VLOOKUP(J16,'Base 1'!$A:$L,12,0),"-") -> - | T16: =IFERROR(VLOOKUP(J16,'Base 1'!$A:$J,10,0),"-") -> - | X16: =IFERROR(VLOOKUP(J16,'Base 1'!$A:$I,9,0),"-") -> - | AC16: =IFERROR(VLOOKUP($J16,'Base 1'!$A:$Q,16,0),"-") -> -
B17: =TODAY() -> 46135 | C17: INDETERMINADO | D17: SANTA CRUZ | E17: =IFERROR(VLOOKUP($J17,'Base 1'!A:S,19,0),"-") -> - | F17: =IFERROR(VLOOKUP($J17,'Base 1'!$A:$N,14,0),"-") -> - | G17: =IFERROR(VLOOKUP($J17,'Base 1'!$A:$O,15,0),"-") -> - | H17: =IFERROR(VLOOKUP($J17,'Base 1'!$A:$T,20,0),"-") -> - | I17: =IFERROR(VLOOKUP($J17,'Base 1'!$A:$C,3,0),"-") -> - | K17: =IFERROR(VLOOKUP($J17,'Base 1'!$A:$E,5,0),"-") -> - | L17: =IFERROR(VLOOKUP($J17,'Base 1'!$A:$B,2,0),"-") -> - | M17: =IFERROR(VLOOKUP($J17,'Base 1'!$A:$Q,17,0),"-") -> - | N17: =IFERROR(VLOOKUP($J17,'Base 1'!$A:$R,18,0),"-") -> - | O17: =IFERROR(VLOOKUP($J17,'Base 1'!$A:$F,6,0),"-") -> - | P17: =IFERROR(VLOOKUP($J17,'Base 1'!$A:$G,7,0),"-") -> - | R17: =IFERROR(VLOOKUP(J17,'Base 1'!$A:$L,12,0),"-") -> - | T17: =IFERROR(VLOOKUP(J17,'Base 1'!$A:$J,10,0),"-") -> - | X17: =IFERROR(VLOOKUP(J17,'Base 1'!$A:$I,9,0),"-") -> - | AC17: =IFERROR(VLOOKUP($J17,'Base 1'!$A:$Q,16,0),"-") -> -
B18: =TODAY() -> 46135 | C18: INDETERMINADO | D18: SANTA CRUZ | E18: =IFERROR(VLOOKUP($J18,'Base 1'!A:S,19,0),"-") -> - | F18: =IFERROR(VLOOKUP($J18,'Base 1'!$A:$N,14,0),"-") -> - | G18: =IFERROR(VLOOKUP($J18,'Base 1'!$A:$O,15,0),"-") -> - | H18: =IFERROR(VLOOKUP($J18,'Base 1'!$A:$T,20,0),"-") -> - | I18: =IFERROR(VLOOKUP($J18,'Base 1'!$A:$C,3,0),"-") -> - | K18: =IFERROR(VLOOKUP($J18,'Base 1'!$A:$E,5,0),"-") -> - | L18: =IFERROR(VLOOKUP($J18,'Base 1'!$A:$B,2,0),"-") -> - | M18: =IFERROR(VLOOKUP($J18,'Base 1'!$A:$Q,17,0),"-") -> - | N18: =IFERROR(VLOOKUP($J18,'Base 1'!$A:$R,18,0),"-") -> - | O18: =IFERROR(VLOOKUP($J18,'Base 1'!$A:$F,6,0),"-") -> - | P18: =IFERROR(VLOOKUP($J18,'Base 1'!$A:$G,7,0),"-") -> - | R18: =IFERROR(VLOOKUP(J18,'Base 1'!$A:$L,12,0),"-") -> - | T18: =IFERROR(VLOOKUP(J18,'Base 1'!$A:$J,10,0),"-") -> - | X18: =IFERROR(VLOOKUP(J18,'Base 1'!$A:$I,9,0),"-") -> - | AC18: =IFERROR(VLOOKUP($J18,'Base 1'!$A:$Q,16,0),"-") -> -
... B748: =TODAY() -> 46135 | C748: INDETERMINADO | D748: SANTA CRUZ | E748: =IFERROR(VLOOKUP($J748,'Base 1'!A:S,19,0),"-") -> - | F748: =IFERROR(VLOOKUP($J748,'Base 1'!$A:$N,14,0),"-") -> - | G748: =IFERROR(VLOOKUP($J748,'Base 1'!$A:$O,15,0),"-") -> - | H748: =IFERROR(VLOOKUP($J748,'Base 1'!$A:$T,20,0),"-") -> - | I748: =IFERROR(VLOOKUP($J748,'Base 1'!$A:$C,3,0),"-") -> - | K748: =IFERROR(VLOOKUP($J748,'Base 1'!$A:$E,5,0),"-") -> - | L748: =IFERROR(VLOOKUP($J748,'Base 1'!$A:$B,2,0),"-") -> - | M748: =IFERROR(VLOOKUP($J748,'Base 1'!$A:$Q,17,0),"-") -> - | N748: =IFERROR(VLOOKUP($J748,'Base 1'!$A:$R,18,0),"-") -> - | O748: =IFERROR(VLOOKUP($J748,'Base 1'!$A:$F,6,0),"-") -> - | P748: =IFERROR(VLOOKUP($J748,'Base 1'!$A:$G,7,0),"-") -> - | R748: =IFERROR(VLOOKUP(J748,'Base 1'!$A:$L,12,0),"-") -> - | T748: =IFERROR(VLOOKUP(J748,'Base 1'!$A:$J,10,0),"-") -> - | X748: =IFERROR(VLOOKUP(J748,'Base 1'!$A:$I,9,0),"-") -> - | AC748: =IFERROR(VLOOKUP($J748,'Base 1'!$A:$Q,16,0),"-") -> -

Sheet MEDIA TRI
H2: Ano | I2: 2026 | J2: 2026 | K2: 2026 | L2: 2026 | M2: 2026 | N2: 2026 | O2: 2026 | P2: 2026 | Q2: 2026 | R2: 2026 | S2: 2026 | T2: 2026 | U2: 2026 | V2: 2026 | W2: 2026 | X2: 2026 | Y2: 2026 | Z2: 2026
H3: Mês | I3: Jan 2026 | J3: Jan 2026 | K3: Jan 2026 | L3: Jan 2026 | M3: Jan 2026 | N3: Jan 2026 | O3: Fev 2026 | P3: Fev 2026 | Q3: Fev 2026 | R3: Fev 2026 | S3: Fev 2026 | T3: Fev 2026 | U3: Mar 2026 | V3: Mar 2026 | W3: Mar 2026 | X3: Mar 2026 | Y3: Mar 2026 | Z3: Mar 2026
B4: Bandeira Agrupada | C4: Band Cliente | D4: Seg Cli | F4: CNPJ | G4: CPF | H4: UF | I4: Meta VB | J4: Meta P.P. VB | K4: VB | L4: Desvio VB | M4: % | N4: Cresc % | O4: Meta VB | P4: Meta P.P. VB | Q4: VB | R4: Desvio VB | S4: % | T4: Cresc % | U4: Meta VB | V4: Meta P.P. VB | W4: VB | X4: Desvio VB | Y4: % | Z4: Cresc % | AA4: MEDIA TRI
B5: Total | I5: =SUBTOTAL(9,I6:I1048576) -> 1.2064471e+08 | J5: =SUBTOTAL(9,J6:J1048576) -> 1.2064471e+08 | K5: =SUBTOTAL(9,K6:K1048576) -> 1.1705069e+08 | L5: -1808390.6 | M5: -0.028655179 | N5: - | O5: =SUBTOTAL(9,O6:O1048576) -> 1.2286468e+08 | P5: =SUBTOTAL(9,P6:P1048576) -> 1.2286468e+08 | Q5: =SUBTOTAL(9,Q6:Q1048576) -> 1.1090509e+08 | R5: -6631802.4 | S5: -0.10447063 | T5: -0.072626577 | U5: =SUBTOTAL(9,U6:U1048576) -> 1.5076836e+08 | V5: =SUBTOTAL(9,V6:V1048576) -> 1.5076836e+08 | W5: =SUBTOTAL(9,W6:W1048576) -> 1.4143219e+08 | X5: -3473084.2 | Y5: -0.046489956 | Z5: 0.25303804 | AA5: =SUM(K5,Q5,W5)/3 -> 1.2312933e+08
A6: =_xlfn.XLOOKUP('[1]CMK - 30.09.2025'!$N$1:$N$1048576,'[1]CMK - 30.09.2025'!$J$1:$J$1048576,"-",0) -> #NAME? | B6: INDIVIDUAL | C6: INDIVIDUAL | D6: INDEPENDENTES | E6: 86860000190 | F6: 00086860000190 - DROGARIA SERRA LTDA | H6: MG | I6: 45264.589 | J6: 45264.589 | K6: 46339.63 | L6: 1075.041 | M6: 0.023750155 | N6: - | O6: 30522.507 | P6: 30522.507 | Q6: 27147.79 | R6: -3374.717 | S6: -0.11056487 | T6: -0.41415609 | U6: 37509.61 | V6: 37509.61 | W6: 53891.02 | X6: 16381.41 | Y6: 0.43672568 | Z6: 0.98509787 | AA6: =SUM(K6,Q6,W6)/3 -> 42459.48
A7: =_xlfn.XLOOKUP('[1]CMK - 30.09.2025'!$N$1:$N$1048576,'[1]CMK - 30.09.2025'!$J$1:$J$1048576,"-",0) -> #NAME? | B7: INDIVIDUAL | C7: INDIVIDUAL | D7: INDEPENDENTES | E7: 112154000175 | F7: 00112154000175 - DROGAZILLE LTDA ME | H7: MG | I7: 5440.774 | J7: 5440.774 | K7: 7055.02 | L7: 1614.246 | M7: 0.29669418 | N7: - | O7: 1451.481 | P7: 1451.481 | Q7: 5016.58 | R7: 3565.099 | S7: 2.4561803 | T7: -0.28893469 | U7: 2963.036 | V7: 2963.036 | W7: 5934.01 | X7: 2970.974 | Y7: 1.002679 | Z7: 0.18287957 | AA7: =SUM(K7,Q7,W7)/3 -> 6001.87
A8: =_xlfn.XLOOKUP('[1]CMK - 30.09.2025'!$N$1:$N$1048576,'[1]CMK - 30.09.2025'!$J$1:$J$1048576,"-",0) -> #NAME? | B8: INDIVIDUAL | C8: INDIVIDUAL | D8: INDEPENDENTES | E8: 149893000131 | F8: 00149893000131 - DROG E PERF TORRES E FILHO LTDA | H8: MG | I8: 4691.774 | J8: 4691.774 | K8: 1771.29 | L8: -2920.484 | M8: -0.62246903 | N8: - | O8: 17281.807 | P8: 17281.807 | Q8: 1298.71 | R8: -15983.097 | S8: -0.92485103 | T8: -0.2667999 | U8: 8846.805 | V8: 8846.805 | W8: 668.69 | X8: -8178.115 | Y8: -0.92441452 | Z8: -0.48511215 | AA8: =SUM(K8,Q8,W8)/3 -> 1246.23
A9: =_xlfn.XLOOKUP('[1]CMK - 30.09.2025'!$N$1:$N$1048576,'[1]CMK - 30.09.2025'!$J$1:$J$1048576,"-",0) -> #NAME? | B9: INDIVIDUAL | C9: INDIVIDUAL | D9: INDEPENDENTES | E9: 204120000100 | F9: 00204120000100 - REGINA RIBEIRO PEIXOTO ME | H9: MG | I9: 1815.92 | J9: 1815.92 | K9: 3022.36 | L9: 1206.44 | M9: 0.66436847 | N9: - | O9: 1964.929 | P9: 1964.929 | Q9: 3050.93 | R9: 1086.001 | S9: 0.55269223 | T9: 0.0094528779 | U9: 1996.988 | V9: 1996.988 | W9: 5093.25 | X9: 3096.262 | Y9: 1.550466 | Z9: 0.669409 | AA9: =SUM(K9,Q9,W9)/3 -> 3722.18
A10: =_xlfn.XLOOKUP('[1]CMK - 30.09.2025'!$N$1:$N$1048576,'[1]CMK - 30.09.2025'!$J$1:$J$1048576,"-",0) -> #NAME? | B10: INDIVIDUAL | C10: INDIVIDUAL | D10: INDEPENDENTES | E10: 207500000107 | F10: 00207500000107 - MULTIMEDIC COMERCIAL LTDA | H10: MG | I10: 38.219 | J10: 38.219 | K10: 0 | L10: -38.219 | M10: -1 | N10: - | O10: 297.141 | P10: 297.141 | Q10: 0 | R10: -297.141 | S10: -1 | T10: - | U10: 66.847 | V10: 66.847 | W10: 0 | X10: -66.847 | Y10: -1 | Z10: - | AA10: =SUM(K10,Q10,W10)/3 -> 0
A11: =_xlfn.XLOOKUP('[1]CMK - 30.09.2025'!$N$1:$N$1048576,'[1]CMK - 30.09.2025'!$J$1:$J$1048576,"-",0) -> #NAME? | B11: INDIVIDUAL | C11: INDIVIDUAL | D11: INDEPENDENTES | E11: 268176000129 | F11: 00268176000129 - DROG SAO JOSE DE NOVA ERA LTDA | H11: MG | I11: 8248.576 | J11: 8248.576 | K11: 4386.82 | L11: -3861.756 | M11: -0.46817245 | N11: - | O11: 17117.66 | P11: 17117.66 | Q11: 6178.08 | R11: -10939.58 | S11: -0.63908151 | T11: 0.40832767 | U11: 26718.28 | V11: 26718.28 | W11: 7392 | X11: -19326.28 | Y11: -0.72333548 | Z11: 0.19648823 | AA11: =SUM(K11,Q11,W11)/3 -> 5985.6333
A12: =_xlfn.XLOOKUP('[1]CMK - 30.09.2025'!$N$1:$N$1048576,'[1]CMK - 30.09.2025'!$J$1:$J$1048576,"-",0) -> #NAME? | B12: INDIVIDUAL | C12: INDIVIDUAL | D12: INDEPENDENTES | E12: 325618000121 | F12: 00325618000121 - DROGARIA JARA LTDA | H12: MG | I12: 10000.933 | J12: 10000.933 | K12: 7422.02 | L12: -2578.913 | M12: -0.25786724 | N12: - | O12: 10298.849 | P12: 10298.849 | Q12: 2992.31 | R12: -7306.539 | S12: -0.709452 | T12: -0.59683348 | U12: 8370.841 | V12: 8370.841 | W12: 7791.47 | X12: -579.371 | Y12: -0.069212998 | Z12: 1.6038312 | AA12: =SUM(K12,Q12,W12)/3 -> 6068.6
A13: =_xlfn.XLOOKUP('[1]CMK - 30.09.2025'!$N$1:$N$1048576,'[1]CMK - 30.09.2025'!$J$1:$J$1048576,"-",0) -> #NAME? | B13: INDIVIDUAL | C13: INDIVIDUAL | D13: INDEPENDENTES | E13: 363241000103 | F13: 00363241000103 - DROG LIMA E BAIAO LTDA ME | H13: MG | I13: 313.35 | J13: 313.35 | K13: 810.07 | L13: 496.72 | M13: 1.5851923 | N13: - | O13: 462.059 | P13: 462.059 | Q13: 574.26 | R13: 112.201 | S13: 0.2428283 | T13: -0.2910983 | U13: 0 | V13: 0 | W13: 514.75 | X13: 514.75 | Y13: - | Z13: -0.10362902 | AA13: =SUM(K13,Q13,W13)/3 -> 633.02667
A14: =_xlfn.XLOOKUP('[1]CMK - 30.09.2025'!$N$1:$N$1048576,'[1]CMK - 30.09.2025'!$J$1:$J$1048576,"-",0) -> #NAME? | B14: INDIVIDUAL | C14: INDIVIDUAL | D14: INDEPENDENTES | E14: 374879000131 | F14: 00374879000131 - ELIANE MARIA BICALHO | H14: MG | I14: 1665.157 | J14: 1665.157 | K14: 1516.69 | L14: -148.467 | M14: -0.089160962 | N14: - | O14: 495.572 | P14: 495.572 | Q14: 248.99 | R14: -246.582 | S14: -0.49757048 | T14: -0.83583329 | U14: 2317.982 | V14: 2317.982 | W14: 531.68 | X14: -1786.302 | Y14: -0.77062807 | Z14: 1.1353468 | AA14: =SUM(K14,Q14,W14)/3 -> 765.78667
A15: =_xlfn.XLOOKUP('[1]CMK - 30.09.2025'!$N$1:$N$1048576,'[1]CMK - 30.09.2025'!$J$1:$J$1048576,"-",0) -> #NAME? | B15: INDIVIDUAL | C15: INDIVIDUAL | D15: INDEPENDENTES | E15: 427688000190 | F15: 00427688000190 - A & D MEDICAMENTOS LTDA | H15: MG | I15: 14026.516 | J15: 14026.516 | K15: 10181.05 | L15: -3845.466 | M15: -0.27415689 | N15: - | O15: 8958.363 | P15: 8958.363 | Q15: 10972.47 | R15: 2014.107 | S15: 0.2248298 | T15: 0.077734615 | U15: 11279.193 | V15: 11279.193 | W15: 14818.84 | X15: 3539.647 | Y15: 0.31382094 | Z15: 0.35054732 | AA15: =SUM(K15,Q15,W15)/3 -> 11990.787
A16: =_xlfn.XLOOKUP('[1]CMK - 30.09.2025'!$N$1:$N$1048576,'[1]CMK - 30.09.2025'!$J$1:$J$1048576,"-",0) -> #NAME? | B16: INDIVIDUAL | C16: INDIVIDUAL | D16: INDEPENDENTES | E16: 517985000127 | F16: 00517985000127 - JOSE CARNEIRO OS & CIA LT ME | H16: MG | I16: 352.965 | J16: 352.965 | K16: 937.81 | L16: 584.845 | M16: 1.656949 | N16: - | O16: 2311.822 | P16: 2311.822 | Q16: 1113.99 | R16: -1197.832 | S16: -0.51813332 | T16: 0.18786321 | U16: 342.385 | V16: 342.385 | W16: 753.98 | X16: 411.595 | Y16: 1.2021409 | Z16: -0.32317166 | AA16: =SUM(K16,Q16,W16)/3 -> 935.26
A17: =_xlfn.XLOOKUP('[1]CMK - 30.09.2025'!$N$1:$N$1048576,'[1]CMK - 30.09.2025'!$J$1:$J$1048576,"-",0) -> #NAME? | B17: INDIVIDUAL | C17: INDIVIDUAL | D17: INDEPENDENTES | E17: 571664000100 | F17: 00571664000100 - DROG MAGALHAES ARAUJO LT | H17: MG | I17: 17355.929 | J17: 17355.929 | K17: 19784.92 | L17: 2428.991 | M17: 0.13995166 | N17: - | O17: 17947.001 | P17: 17947.001 | Q17: 23613.58 | R17: 5666.579 | S17: 0.3157396 | T17: 0.19351405 | U17: 25082.974 | V17: 25082.974 | W17: 34433.63 | X17: 9350.656 | Y17: 0.37278897 | Z17: 0.45821303 | AA17: =SUM(K17,Q17,W17)/3 -> 25944.043
A18: =_xlfn.XLOOKUP('[1]CMK - 30.09.2025'!$N$1:$N$1048576,'[1]CMK - 30.09.2025'!$J$1:$J$1048576,"-",0) -> #NAME? | B18: INDIVIDUAL | C18: INDIVIDUAL | D18: INDEPENDENTES | E18: 592069000151 | F18: 00592069000151 - FABIO FERREIRA DA SILVA | H18: MG | I18: 14913.844 | J18: 14913.844 | K18: 24461.92 | L18: 9548.076 | M18: 0.64021563 | N18: - | O18: 12227.216 | P18: 12227.216 | Q18: 8732.4 | R18: -3494.816 | S18: -0.28582271 | T18: -0.64302066 | U18: 13282.631 | V18: 13282.631 | W18: 4802.4 | X18: -8480.231 | Y18: -0.63844512 | Z18: -0.4500481 | AA18: =SUM(K18,Q18,W18)/3 -> 12665.573
A19: =_xlfn.XLOOKUP('[1]CMK - 30.09.2025'!$N$1:$N$1048576,'[1]CMK - 30.09.2025'!$J$1:$J$1048576,"-",0) -> #NAME? | B19: INDIVIDUAL | C19: INDIVIDUAL | D19: INDEPENDENTES | E19: 595692000168 | F19: 00595692000168 - GILSON JOSE DE MATOS ME | H19: MG | I19: 1048.504 | J19: 1048.504 | K19: 1045.53 | L19: -2.974 | M19: -0.0028364222 | N19: - | O19: 1210.733 | P19: 1210.733 | Q19: 676.67 | R19: -534.063 | S19: -0.44110716 | T19: -0.35279715 | U19: 2080.785 | V19: 2080.785 | W19: 1428.32 | X19: -652.465 | Y19: -0.31356675 | Z19: 1.1108073 | AA19: =SUM(K19,Q19,W19)/3 -> 1050.1733
A20: =_xlfn.XLOOKUP('[1]CMK - 30.09.2025'!$N$1:$N$1048576,'[1]CMK - 30.09.2025'!$J$1:$J$1048576,"-",0) -> #NAME? | B20: INDIVIDUAL | C20: INDIVIDUAL | D20: INDEPENDENTES | E20: 600161000116 | F20: 00600161000116 - FARMACIA GOMES & OLIVEIRA LTDA | H20: MG | I20: 6761.644 | J20: 6761.644 | K20: 1206.84 | L20: -5554.804 | M20: -0.82151678 | N20: - | O20: 17659.458 | P20: 17659.458 | Q20: 1799.26 | R20: -15860.198 | S20: -0.89811352 | T20: 0.49088529 | U20: 10427.283 | V20: 10427.283 | W20: 4967.94 | X20: -5459.343 | Y20: -0.52356333 | Z20: 1.7611018 | AA20: =SUM(K20,Q20,W20)/3 -> 2658.0133
A21: =_xlfn.XLOOKUP('[1]CMK - 30.09.2025'!$N$1:$N$1048576,'[1]CMK - 30.09.2025'!$J$1:$J$1048576,"-",0) -> #NAME? | B21: INDIVIDUAL | C21: INDIVIDUAL | D21: INDEPENDENTES | E21: 614946000148 | F21: 00614946000148 - DROGA MED REIS LTDA | H21: MG | I21: 554.788 | J21: 554.788 | K21: 1393.6 | L21: 838.812 | M21: 1.5119505 | N21: - | O21: 1385.398 | P21: 1385.398 | Q21: 1557.49 | R21: 172.092 | S21: 0.12421846 | T21: 0.11760189 | U21: 5592.523 | V21: 5592.523 | W21: 1674.26 | X21: -3918.263 | Y21: -0.70062528 | Z21: 0.074973194 | AA21: =SUM(K21,Q21,W21)/3 -> 1541.7833
A22: =_xlfn.XLOOKUP('[1]CMK - 30.09.2025'!$N$1:$N$1048576,'[1]CMK - 30.09.2025'!$J$1:$J$1048576,"-",0) -> #NAME? | B22: INDIVIDUAL | C22: INDIVIDUAL | D22: INDEPENDENTES | E22: 616871000134 | F22: 00616871000134 - FARMACIA DO PAULINHO EIRELI | H22: MG | I22: 1608.494 | J22: 1608.494 | K22: 1136.82 | L22: -471.674 | M22: -0.29323951 | N22: - | O22: 860.253 | P22: 860.253 | Q22: 708.76 | R22: -151.493 | S22: -0.17610284 | T22: -0.37654158 | U22: 1462.302 | V22: 1462.302 | W22: 1217.26 | X22: -245.042 | Y22: -0.16757277 | Z22: 0.71745019 | AA22: =SUM(K22,Q22,W22)/3 -> 1020.9467
A23: =_xlfn.XLOOKUP('[1]CMK - 30.09.2025'!$N$1:$N$1048576,'[1]CMK - 30.09.2025'!$J$1:$J$1048576,"-",0) -> #NAME? | B23: INDIVIDUAL | C23: INDIVIDUAL | D23: INDEPENDENTES | E23: 619378000178 | F23: 00619378000178 - FCIA E DROG LUERSEN LT | H23: MG | I23: - | J23: - | K23: - | L23: - | M23: - | N23: - | O23: - | P23: - | Q23: - | R23: - | S23: - | T23: - | U23: 0 | V23: 0 | W23: 714.92 | X23: 714.92 | Y23: - | Z23: - | AA23: =SUM(K23,Q23,W23)/3 -> 238.30667
A24: =_xlfn.XLOOKUP('[1]CMK - 30.09.2025'!$N$1:$N$1048576,'[1]CMK - 30.09.2025'!$J$1:$J$1048576,"-",0) -> #NAME? | B24: INDIVIDUAL | C24: INDIVIDUAL | D24: INDEPENDENTES | E24: 624132000194 | F24: 00624132000194 - SAULO BRUNO ALVES E CIA LTDA | H24: MG | I24: 9699.609 | J24: 9699.609 | K24: 19479.11 | L24: 9779.501 | M24: 1.0082366 | N24: - | O24: 2329.763 | P24: 2329.763 | Q24: 718.09 | R24: -1611.673 | S24: -0.69177552 | T24: -0.96313538 | U24: 98.96 | V24: 98.96 | W24: 730.91 | X24: 631.95 | Y24: 6.3859135 | Z24: 0.017852915 | AA24: =SUM(K24,Q24,W24)/3 -> 6976.0367
A25: =_xlfn.XLOOKUP('[1]CMK - 30.09.2025'!$N$1:$N$1048576,'[1]CMK - 30.09.2025'!$J$1:$J$1048576,"-",0) -> #NAME? | B25: INDIVIDUAL | C25: INDIVIDUAL | D25: INDEPENDENTES | E25: 794195000199 | F25: 00794195000199 - DROGARIA MARILENE DRUGSTORE LTDA | H25: MG | I25: 8353.166 | J25: 8353.166 | K25: 16120.33 | L25: 7767.164 | M25: 0.92984672 | N25: - | O25: 5692.939 | P25: 5692.939 | Q25: 15306.81 | R25: 9613.871 | S25: 1.688736 | T25: -0.050465468 | U25: 8290.001 | V25: 8290.001 | W25: 20407.67 | X25: 12117.669 | Y25: 1.4617211 | Z25: 0.33324122 | AA25: =SUM(K25,Q25,W25)/3 -> 17278.27
A26: =_xlfn.XLOOKUP('[1]CMK - 30.09.2025'!$N$1:$N$1048576,'[1]CMK - 30.09.2025'!$J$1:$J$1048576,"-",0) -> #NAME? | B26: INDIVIDUAL | C26: INDIVIDUAL | D26: INDEPENDENTES | E26: 808730000113 | F26: 00808730000113 - ELEMENTAR DROGARIAS LTDA | H26: MG | I26: 39936.619 | J26: 39936.619 | K26: 19971.84 | L26: -19964.779 | M26: -0.4999116 | N26: - | O26: 33969.634 | P26: 33969.634 | Q26: 19905.99 | R26: -14063.644 | S26: -0.41400634 | T26: -0.0032971424 | U26: 58686.035 | V26: 58686.035 | W26: 33510.48 | X26: -25175.555 | Y26: -0.42898715 | Z26: 0.683437 | AA26: =SUM(K26,Q26,W26)/3 -> 24462.77
A27: =_xlfn.XLOOKUP('[1]CMK - 30.09.2025'!$N$1:$N$1048576,'[1]CMK - 30.09.2025'!$J$1:$J$1048576,"-",0) -> #NAME? | B27: INDIVIDUAL | C27: INDIVIDUAL | D27: INDEPENDENTES | E27: 808730000709 | F27: 00808730000709 - ELEMENTAR DROGARIAS LTDA EPP | H27: MG | I27: 81121.781 | J27: 81121.781 | K27: 51051.98 | L27: -30069.801 | M27: -0.37067481 | N27: - | O27: 67958.471 | P27: 67958.471 | Q27: 40767.02 | R27: -27191.451 | S27: -0.40011864 | T27: -0.20146055 | U27: 97055.663 | V27: 97055.663 | W27: 50569.9 | X27: -46485.763 | Y27: -0.47895982 | Z27: 0.24046104 | AA27: =SUM(K27,Q27,W27)/3 -> 47462.967
A28: =_xlfn.XLOOKUP('[1]CMK - 30.09.2025'!$N$1:$N$1048576,'[1]CMK - 30.09.2025'!$J$1:$J$1048576,"-",0) -> #NAME? | B28: INDIVIDUAL | C28: INDIVIDUAL | D28: INDEPENDENTES | E28: 823568000102 | F28: 00823568000102 - ORG REIS ARAUJO LTDA ME | H28: MG | I28: 9178.908 | J28: 9178.908 | K28: 5803.05 | L28: -3375.858 | M28: -0.36778427 | N28: - | O28: 10457.922 | P28: 10457.922 | Q28: 3632.87 | R28: -6825.052 | S28: -0.65262028 | T28: -0.37397231 | U28: 17807.597 | V28: 17807.597 | W28: 6209.69 | X28: -11597.907 | Y28: -0.65128984 | Z28: 0.70930697 | AA28: =SUM(K28,Q28,W28)/3 -> 5215.2033
A29: =_xlfn.XLOOKUP('[1]CMK - 30.09.2025'!$N$1:$N$1048576,'[1]CMK - 30.09.2025'!$J$1:$J$1048576,"-",0) -> #NAME? | B29: INDIVIDUAL | C29: INDIVIDUAL | D29: INDEPENDENTES | E29: 858625000199 | F29: 00858625000199 - DROGARIA CAJU DE FRUTAL LTDA | H29: MG | I29: 3225.929 | J29: 3225.929 | K29: 2948.15 | L29: -277.779 | M29: -0.086108219 | N29: - | O29: 429.235 | P29: 429.235 | Q29: 92.77 | R29: -336.465 | S29: -0.78387131 | T29: -0.96853281 | U29: 209.152 | V29: 209.152 | W29: 0 | X29: -209.152 | Y29: -1 | Z29: -1 | AA29: =SUM(K29,Q29,W29)/3 -> 1013.64
A30: =_xlfn.XLOOKUP('[1]CMK - 30.09.2025'!$N$1:$N$1048576,'[1]CMK - 30.09.2025'!$J$1:$J$1048576,"-",0) -> #NAME? | B30: INDIVIDUAL | C30: INDIVIDUAL | D30: INDEPENDENTES | E30: 861004000164 | F30: 00861004000164 - CAROL MEDICAMENTOS LTDA | H30: MG | I30: 2009.721 | J30: 2009.721 | K30: 956.55 | L30: -1053.171 | M30: -0.52403841 | N30: - | O30: 1546.64 | P30: 1546.64 | Q30: 742.15 | R30: -804.49 | S30: -0.52015336 | T30: -0.22413883 | U30: 4256.497 | V30: 4256.497 | W30: 1479.89 | X30: -2776.607 | Y30: -0.65232209 | Z30: 0.99405781 | AA30: =SUM(K30,Q30,W30)/3 -> 1059.53
A31: =_xlfn.XLOOKUP('[1]CMK - 30.09.2025'!$N$1:$N$1048576,'[1]CMK - 30.09.2025'!$J$1:$J$1048576,"-",0) -> #NAME? | B31: INDIVIDUAL | C31: INDIVIDUAL | D31: INDEPENDENTES | E31: 887337000162 | F31: 00887337000162 - REIS & MATOS LTDA | H31: MG | I31: 11791.021 | J31: 11791.021 | K31: 21275.43 | L31: 9484.409 | M31: 0.80437555 | N31: - | O31: 15551.836 | P31: 15551.836 | Q31: 13603.95 | R31: -1947.886 | S31: -0.12525119 | T31: -0.36057932 | U31: 19639.423 | V31: 19639.423 | W31: 17534.53 | X31: -2104.893 | Y31: -0.10717693 | Z31: 0.28892932 | AA31: =SUM(K31,Q31,W31)/3 -> 17471.303
A32: =_xlfn.XLOOKUP('[1]CMK - 30.09.2025'!$N$1:$N$1048576,'[1]CMK - 30.09.2025'!$J$1:$J$1048576,"-",0) -> #NAME? | B32: INDIVIDUAL | C32: INDIVIDUAL | D32: INDEPENDENTES | E32: 969186000191 | F32: 00969186000191 - DROGARIA 3R & V LTDA ME | H32: MG | I32: 17795.741 | J32: 17795.741 | K32: 17603.04 | L32: -192.701 | M32: -0.01082849 | N32: - | O32: 15040.282 | P32: 15040.282 | Q32: 15643.46 | R32: 603.178 | S32: 0.040104168 | T32: -0.11132054 | U32: 16919.165 | V32: 16919.165 | W32: 20854.76 | X32: 3935.595 | Y32: 0.23261166 | Z32: 0.33312963 | AA32: =SUM(K32,Q32,W32)/3 -> 18033.753
A33: =_xlfn.XLOOKUP('[1]CMK - 30.09.2025'!$N$1:$N$1048576,'[1]CMK - 30.09.2025'!$J$1:$J$1048576,"-",0) -> #NAME? | B33: INDIVIDUAL | C33: INDIVIDUAL | D33: INDEPENDENTES | E33: 981525000155 | F33: 00981525000155 - MENDONCA & MENDONCA LTDA ME | H33: MG | I33: - | J33: - | K33: - | L33: - | M33: - | N33: - | O33: 0 | P33: 0 | Q33: 1002.3 | R33: 1002.3 | S33: - | T33: - | U33: 0 | V33: 0 | W33: 0 | X33: 0 | Y33: - | Z33: -1 | AA33: =SUM(K33,Q33,W33)/3 -> 334.1
A34: =_xlfn.XLOOKUP('[1]CMK - 30.09.2025'!$N$1:$N$1048576,'[1]CMK - 30.09.2025'!$J$1:$J$1048576,"-",0) -> #NAME? | B34: INDIVIDUAL | C34: INDIVIDUAL | D34: INDEPENDENTES | E34: 1001654000100 | F34: 01001654000100 - JOSE OSORIO FERREIRA & CIA LT | H34: MG | I34: 1426.98 | J34: 1426.98 | K34: 1613.52 | L34: 186.54 | M34: 0.13072363 | N34: - | O34: 3696.914 | P34: 3696.914 | Q34: 516.6 | R34: -3180.314 | S34: -0.86026183 | T34: -0.67983043 | U34: 2583.379 | V34: 2583.379 | W34: 1003.33 | X34: -1580.049 | Y34: -0.61162106 | Z34: 0.94217964 | AA34: =SUM(K34,Q34,W34)/3 -> 1044.4833
A35: =_xlfn.XLOOKUP('[1]CMK - 30.09.2025'!$N$1:$N$1048576,'[1]CMK - 30.09.2025'!$J$1:$J$1048576,"-",0) -> #NAME? | B35: INDIVIDUAL | C35: INDIVIDUAL | D35: INDEPENDENTES | E35: 1091254000125 | F35: 01091254000125 - ELIANA IGNACIO FERNANDES E SILVA | H35: MG | I35: 453.764 | J35: 453.764 | K35: 640.06 | L35: 186.296 | M35: 0.41055703 | N35: - | O35: 200.424 | P35: 200.424 | Q35: 71.1 | R35: -129.324 | S35: -0.64525207 | T35: -0.88891666 | U35: 387.627 | V35: 387.627 | W35: 601.86 | X35: 214.233 | Y35: 0.55267822 | Z35: 7.4649789 | AA35: =SUM(K35,Q35,W35)/3 -> 437.67333
A36: =_xlfn.XLOOKUP('[1]CMK - 30.09.2025'!$N$1:$N$1048576,'[1]CMK - 30.09.2025'!$J$1:$J$1048576,"-",0) -> #NAME? | B36: INDIVIDUAL | C36: INDIVIDUAL | D36: INDEPENDENTES | E36: 1122922000134 | F36: 01122922000134 - DROGALON LTDA ME | H36: MG | I36: 54.919 | J36: 54.919 | K36: 372.78 | L36: 317.861 | M36: 5.7878148 | N36: - | O36: 0 | P36: 0 | Q36: 0 | R36: 0 | S36: - | T36: -1 | U36: 70.289 | V36: 70.289 | W36: 112.16 | X36: 41.871 | Y36: 0.59569776 | Z36: - | AA36: =SUM(K36,Q36,W36)/3 -> 161.64667
A37: =_xlfn.XLOOKUP('[1]CMK - 30.09.2025'!$N$1:$N$1048576,'[1]CMK - 30.09.2025'!$J$1:$J$1048576,"-",0) -> #NAME? | B37: INDIVIDUAL | C37: INDIVIDUAL | D37: INDEPENDENTES | E37: 1218314000128 | F37: 01218314000128 - HELIO ANTONIO MACHADO LTDA | H37: MG | I37: 12550.637 | J37: 12550.637 | K37: 20741.64 | L37: 8191.003 | M37: 0.65263644 | N37: - | O37: 14121.031 | P37: 14121.031 | Q37: 40056.61 | R37: 25935.579 | S37: 1.8366633 | T37: 0.93121711 | U37: 16015.567 | V37: 16015.567 | W37: 17253.39 | X37: 1237.823 | Y37: 0.07728874 | Z37: -0.56927483 | AA37: =SUM(K37,Q37,W37)/3 -> 26017.213
A38: =_xlfn.XLOOKUP('[1]CMK - 30.09.2025'!$N$1:$N$1048576,'[1]CMK - 30.09.2025'!$J$1:$J$1048576,"-",0) -> #NAME? | B38: INDIVIDUAL | C38: INDIVIDUAL | D38: INDEPENDENTES | E38: 1379836000101 | F38: 01379836000101 - DROG PERF S R VITERBO LTDA ME | H38: MG | I38: 3480.026 | J38: 3480.026 | K38: 2600.25 | L38: -879.776 | M38: -0.25280731 | N38: - | O38: 8875.334 | P38: 8875.334 | Q38: 1349.69 | R38: -7525.644 | S38: -0.84792798 | T38: -0.48093837 | U38: 6573.932 | V38: 6573.932 | W38: 3824.77 | X38: -2749.162 | Y38: -0.41819143 | Z38: 1.8338137 | AA38: =SUM(K38,Q38,W38)/3 -> 2591.57
A39: =_xlfn.XLOOKUP('[1]CMK - 30.09.2025'!$N$1:$N$1048576,'[1]CMK - 30.09.2025'!$J$1:$J$1048576,"-",0) -> #NAME? | B39: INDIVIDUAL | C39: INDIVIDUAL | D39: INDEPENDENTES | E39: 1416103000108 | F39: 01416103000108 - J E G MEDICAMENTOS E PERFUMARIA LTD | H39: MG | I39: 3162.508 | J39: 3162.508 | K39: 3656.88 | L39: 494.372 | M39: 0.15632277 | N39: - | O39: 2839.145 | P39: 2839.145 | Q39: 1935.14 | R39: -904.005 | S39: -0.31840748 | T39: -0.47082212 | U39: 3347.925 | V39: 3347.925 | W39: 3446.62 | X39: 98.695 | Y39: 0.029479454 | Z39: 0.7810701 | AA39: =SUM(K39,Q39,W39)/3 -> 3012.88
A40: =_xlfn.XLOOKUP('[1]CMK - 30.09.2025'!$N$1:$N$1048576,'[1]CMK - 30.09.2025'!$J$1:$J$1048576,"-",0) -> #NAME? | B40: INDIVIDUAL | C40: INDIVIDUAL | D40: INDEPENDENTES | E40: 1417694000120 | F40: 01417694000120 - DISTRIMIX DIST DE MED LTDA | H40: MG | I40: 18110.764 | J40: 18110.764 | K40: 11863.11 | L40: -6247.654 | M40: -0.3449691 | N40: - | O40: 26008.069 | P40: 26008.069 | Q40: 22696.84 | R40: -3311.229 | S40: -0.12731545 | T40: 0.91322849 | U40: 45830.996 | V40: 45830.996 | W40: 15113.51 | X40: -30717.486 | Y40: -0.67023387 | Z40: -0.33411391 | AA40: =SUM(K40,Q40,W40)/3 -> 16557.82
A41: =_xlfn.XLOOKUP('[1]CMK - 30.09.2025'!$N$1:$N$1048576,'[1]CMK - 30.09.2025'!$J$1:$J$1048576,"-",0) -> #NAME? | B41: INDIVIDUAL | C41: INDIVIDUAL | D41: INDEPENDENTES | E41: 1468894000101 | F41: 01468894000101 - DROGARIA ANGELO RONCALLI LTDA | H41: MG | I41: 2176.175 | J41: 2176.175 | K41: 1806.13 | L41: -370.045 | M41: -0.17004377 | N41: - | O41: 487.969 | P41: 487.969 | Q41: 1539.52 | R41: 1051.551 | S41: 2.1549545 | T41: -0.14761396 | U41: 1081.998 | V41: 1081.998 | W41: 2617.32 | X41: 1535.322 | Y41: 1.4189694 | Z41: 0.70008834 | AA41: =SUM(K41,Q41,W41)/3 -> 1987.6567
...

Sheet Base 1
A1: CODIGO | B1: CNPJ | C1: COD SAP CLIENTE | D1: SET | E1: RAZÃO SOCIAL | F1: COD. BAND. | G1: BANDEIRA | H1: COND PZ | I1: DIAS PZ | J1: COND AV | K1: DIAS AV | L1: MATRIZ | M1: STATUS | N1: NOME GV | O1: NOME SUP | P1: MEDIA TRI | Q1: COD REDE | R1: REDE | S1: FILIAL | T1: ORG VENDAS | U1: CNPJ | V1: Grp.preço | W1: Den.Grp.Preços
A2: B00006 | B2: 42849414000130 | C2: 101414 | D2: 207 | E2: DROGARIA NESTORAO LTDA | F2: 10437 | G2: INDIVIDUAL | H2: 35993 | I2: 30 | J2: 35993 | K2: 7 | L2: B00006 | M2: ATIVO | N2: GABRIEL GONCALVES FONSECA | O2: ALEX DE SOUSA PEREIRA | P2: =_xlfn.XLOOKUP('MEDIA TRI'!$E:$E,'MEDIA TRI'!$AA:$AA,"-",0) -> #NAME? | Q2: =_xlfn.XLOOKUP($U:$U,$V:$V,0,0) -> #NAME? | R2: =_xlfn.XLOOKUP($U:$U,$W:$W,0,0) -> #NAME? | S2: MG | T2: MG | U2: 57214900000230 | V2: O4 | W2: DROGARIA TOTAL
A3: B00014 | B3: 21217971000168 | C3: 134634 | D3: 1791 | E3: DROGARIA AMARANTE LTDA | F3: 10437 | G3: INDIVIDUAL | H3: 35186 | I3: 28 | J3: 35186 | K3: 7 | L3: B00014 | M3: ATIVO | N3: GABRIEL GONCALVES FONSECA | O3: ANDRE DIAS DE OLIVEIRA | P3: =_xlfn.XLOOKUP('MEDIA TRI'!$E:$E,'MEDIA TRI'!$AA:$AA,"-",0) -> #NAME? | Q3: =_xlfn.XLOOKUP($U:$U,$V:$V,0,0) -> #NAME? | R3: =_xlfn.XLOOKUP($U:$U,$W:$W,0,0) -> #NAME? | S3: MG | T3: MG | U3: 57214900000230 | V3: O4 | W3: DROGARIA TOTAL
A4: B00016 | B4: 9440889000100 | C4: 125405 | D4: 542 | E4: DROGARIA BORBOLETA LTDA | F4: 14516 | G4: ABRAFAD REDE SOMA | H4: 35195 | I4: 27 | J4: 35195 | K4: 7 | L4: B00016 | M4: ATIVO | N4: JULIANO DE MOURA HIDAKA | O4: VAGO - ZONA DA MATA - MG | P4: =_xlfn.XLOOKUP('MEDIA TRI'!$E:$E,'MEDIA TRI'!$AA:$AA,"-",0) -> #NAME? | Q4: =_xlfn.XLOOKUP($U:$U,$V:$V,0,0) -> #NAME? | R4: =_xlfn.XLOOKUP($U:$U,$W:$W,0,0) -> #NAME? | S4: MG | T4: MGI | U4: 87497368000195 | V4: 1P | W4: MIX FARMA
A5: B00018 | B5: 9519515000177 | C5: 105857 | D5: 1146 | E5: DROGARIA E FARMACIA LOGOS LTDA | F5: 10437 | G5: INDIVIDUAL | H5: 36001 | I5: 28 | J5: 36001 | K5: 7 | L5: B00018 | M5: ATIVO | N5: GABRIEL GONCALVES FONSECA | O5: INATIVO - MG3 | P5: =_xlfn.XLOOKUP('MEDIA TRI'!$E:$E,'MEDIA TRI'!$AA:$AA,"-",0) -> #NAME? | Q5: =_xlfn.XLOOKUP($U:$U,$V:$V,0,0) -> #NAME? | R5: =_xlfn.XLOOKUP($U:$U,$W:$W,0,0) -> #NAME? | S5: MG | T5: MG | U5: 87497368000195 | V5: 1P | W5: MIX FARMA
A6: B00021 | B6: 71159388000469 | C6: 116212 | D6: 1440 | E6: NOSSAS ERVAS PROD NATURIAS LTD | F6: 95 | G6: REDEFARMA | H6: 35999 | I6: 28 | J6: 35999 | K6: 7 | L6: B07670 | M6: ATIVO | N6: JULIANO DE MOURA HIDAKA | O6: LUIS CARLOS SILVEIRA | P6: =_xlfn.XLOOKUP('MEDIA TRI'!$E:$E,'MEDIA TRI'!$AA:$AA,"-",0) -> #NAME? | Q6: =_xlfn.XLOOKUP($U:$U,$V:$V,0,0) -> #NAME? | R6: =_xlfn.XLOOKUP($U:$U,$W:$W,0,0) -> #NAME? | S6: MG | T6: MG | U6: 82602327000360 | V6: 1P | W6: MIX FARMA
A7: B00022 | B7: 17601675000199 | C7: 130363 | D7: 529 | E7: DROGARIA LPP LTDA EPP | F7: 14608 | G7: HIPER SAUDE | H7: 34925 | I7: 42 | J7: 34925 | K7: 7 | L7: B00022 | M7: ATIVO | N7: JULIANO DE MOURA HIDAKA | O7: VAGNER LUIZ BUENO CAMBRAIA | P7: =_xlfn.XLOOKUP('MEDIA TRI'!$E:$E,'MEDIA TRI'!$AA:$AA,"-",0) -> #NAME? | Q7: =_xlfn.XLOOKUP($U:$U,$V:$V,0,0) -> #NAME? | R7: =_xlfn.XLOOKUP($U:$U,$W:$W,0,0) -> #NAME? | S7: MG | T7: MGI | U7: 82602327000360 | V7: 1P | W7: MIX FARMA
A8: B00023 | B8: 9408863000177 | C8: 147363 | D8: 1146 | E8: PLENA DROG E COM LT | F8: 14329 | G8: ABRAFAD MELHORCOMPRA | H8: 30015 | I8: 21 | J8: 30015 | K8: 7 | L8: B00023 | M8: ATIVO | N8: GABRIEL GONCALVES FONSECA | O8: INATIVO - MG3 | P8: =_xlfn.XLOOKUP('MEDIA TRI'!$E:$E,'MEDIA TRI'!$AA:$AA,"-",0) -> #NAME? | Q8: =_xlfn.XLOOKUP($U:$U,$V:$V,0,0) -> #NAME? | R8: =_xlfn.XLOOKUP($U:$U,$W:$W,0,0) -> #NAME? | S8: MG | T8: MG | U8: 1647867000287 | V8: 5H | W8: UNIMED MG
A9: B00024 | B9: 9398614000148 | C9: 131002 | D9: 363 | E9: DROGARIA ALVARENGA E FERREIRA | F9: 10437 | G9: INDIVIDUAL | H9: 34924 | I9: 26 | J9: 34924 | K9: 7 | L9: B00024 | M9: ATIVO | N9: JULIANO DE MOURA HIDAKA | O9: LUIS CARLOS SILVEIRA | P9: =_xlfn.XLOOKUP('MEDIA TRI'!$E:$E,'MEDIA TRI'!$AA:$AA,"-",0) -> #NAME? | Q9: =_xlfn.XLOOKUP($U:$U,$V:$V,0,0) -> #NAME? | R9: =_xlfn.XLOOKUP($U:$U,$W:$W,0,0) -> #NAME? | S9: MG | T9: MG | U9: 1647867000287 | V9: 5H | W9: UNIMED MG
A10: B00025 | B10: 9409548000164 | C10: 105173 | D10: 2255 | E10: DROGARIA TUTA S LTDA | F10: 10437 | G10: INDIVIDUAL | H10: 35999 | I10: 7 | J10: 35999 | K10: 7 | L10: B00025 | M10: ATIVO | N10: GABRIEL GONCALVES FONSECA | O10: CIRO DE CARVALHO MIRANDA | P10: =_xlfn.XLOOKUP('MEDIA TRI'!$E:$E,'MEDIA TRI'!$AA:$AA,"-",0) -> #NAME? | Q10: =_xlfn.XLOOKUP($U:$U,$V:$V,0,0) -> #NAME? | R10: =_xlfn.XLOOKUP($U:$U,$W:$W,0,0) -> #NAME? | S10: MG | T10: MG | U10: 45359213000223 | V10: HW | W10: REDE UNIMED SAO CARL
A11: B00026 | B11: 21705181000121 | C11: 106994 | D11: 512 | E11: DROGARIA MATOS LTDA | F11: 14261 | G11: FARMELHOR | H11: 35993 | I11: 28 | J11: 35993 | K11: 7 | L11: B00026 | M11: ATIVO | N11: JULIANO DE MOURA HIDAKA | O11: DOUGLAS ALCANTARA PEREIRA | P11: =_xlfn.XLOOKUP('MEDIA TRI'!$E:$E,'MEDIA TRI'!$AA:$AA,"-",0) -> #NAME? | Q11: =_xlfn.XLOOKUP($U:$U,$V:$V,0,0) -> #NAME? | R11: =_xlfn.XLOOKUP($U:$U,$W:$W,0,0) -> #NAME? | S11: MG | T11: MGI | U11: 45359213000223 | V11: HW | W11: REDE UNIMED SAO CARL
A12: B00027 | B12: 23954233000200 | C12: 138036 | D12: 3412 | E12: DROGA MELLO LTDA | F12: 10437 | G12: INDIVIDUAL | H12: 30015 | I12: 21 | J12: 30015 | K12: 7 | L12: B26225 | M12: ATIVO | N12: JULIANO DE MOURA HIDAKA | O12: INATIVO - MG4 | P12: =_xlfn.XLOOKUP('MEDIA TRI'!$E:$E,'MEDIA TRI'!$AA:$AA,"-",0) -> #NAME? | Q12: =_xlfn.XLOOKUP($U:$U,$V:$V,0,0) -> #NAME? | R12: =_xlfn.XLOOKUP($U:$U,$W:$W,0,0) -> #NAME? | S12: MG | T12: MGI | U12: 69087922000427 | V12: 1P | W12: MIX FARMA
A13: B00028 | B13: 26046821000152 | C13: 110720 | D13: 1792 | E13: CENTRO ESP N SRA D ASSUNCAO LT | F13: 10437 | G13: INDIVIDUAL | H13: 35186 | I13: 27 | J13: 35186 | K13: 7 | L13: B00028 | M13: ATIVO | N13: JULIANO DE MOURA HIDAKA | O13: VAGO - ZONA DA MATA - MG | P13: =_xlfn.XLOOKUP('MEDIA TRI'!$E:$E,'MEDIA TRI'!$AA:$AA,"-",0) -> #NAME? | Q13: =_xlfn.XLOOKUP($U:$U,$V:$V,0,0) -> #NAME? | R13: =_xlfn.XLOOKUP($U:$U,$W:$W,0,0) -> #NAME? | S13: MG | T13: MG | U13: 69087922000427 | V13: 1P | W13: MIX FARMA
... A19: B00055 | B19: 1072371000141 | C19: 117710 | D19: 2069 | E19: COMERCIAL BARRON LTDA | F19: 14157 | G19: LUMAF | H19: 35999 | I19: 21 | J19: 35999 | K19: 7 | L19: B00055 | M19: ATIVO | N19: GABRIEL GONCALVES FONSECA | O19: THIAGO DE CASTRO MARIA | P19: =_xlfn.XLOOKUP('MEDIA TRI'!$E:$E,'MEDIA TRI'!$AA:$AA,"-",0) -> #NAME? | Q19: =_xlfn.XLOOKUP($U:$U,$V:$V,0,0) -> #NAME? | R19: =_xlfn.XLOOKUP($U:$U,$W:$W,0,0) -> #NAME? | S19: MG | T19: MGI | U19: 87300448000109 | V19: 1P | W19: MIX FARMA
A20: B00063 | B20: 71166672000110 | C20: 114104 | D20: 388 | E20: DROG PASSAGEM DE MARIANA LT ME | F20: 10437 | G20: INDIVIDUAL | H20: 34841 | I20: 35 | J20: 34841 | K20: 7 | L20: B00063 | M20: ATIVO | N20: GABRIEL GONCALVES FONSECA | O20: CIRO DE CARVALHO MIRANDA | P20: =_xlfn.XLOOKUP('MEDIA TRI'!$E:$E,'MEDIA TRI'!$AA:$AA,"-",0) -> #NAME? | Q20: =_xlfn.XLOOKUP($U:$U,$V:$V,0,0) -> #NAME? | R20: =_xlfn.XLOOKUP($U:$U,$W:$W,0,0) -> #NAME? | S20: MG | T20: MG | U20: 3980208000102 | V20: 28 | W20: MIX FARMA B
A21: B00071 | B21: 7386243000159 | C21: 114563 | D21: 1791 | E21: DROGARIA BARROS E GOMES LTDA | F21: 14516 | G21: ABRAFAD REDE SOMA | H21: 34925 | I21: 35 | J21: 34925 | K21: 7 | L21: B00071 | M21: ATIVO | N21: GABRIEL GONCALVES FONSECA | O21: ANDRE DIAS DE OLIVEIRA | P21: =_xlfn.XLOOKUP('MEDIA TRI'!$E:$E,'MEDIA TRI'!$AA:$AA,"-",0) -> #NAME? | Q21: =_xlfn.XLOOKUP($U:$U,$V:$V,0,0) -> #NAME? | R21: =_xlfn.XLOOKUP($U:$U,$W:$W,0,0) -> #NAME? | S21: MG | T21: MG | U21: 3980208000102 | V21: 28 | W21: MIX FARMA B
A22: B00121 | B22: 66342650000123 | C22: 127643 | D22: 302 | E22: DROGARIA KARISHA LTDA ME | F22: 10437 | G22: INDIVIDUAL | H22: 35998 | I22: 35 | J22: 35998 | K22: 7 | L22: B00121 | M22: ATIVO | N22: GABRIEL GONCALVES FONSECA | O22: GUSTAVO GONCALVES | P22: =_xlfn.XLOOKUP('MEDIA TRI'!$E:$E,'MEDIA TRI'!$AA:$AA,"-",0) -> #NAME? | Q22: =_xlfn.XLOOKUP($U:$U,$V:$V,0,0) -> #NAME? | R22: =_xlfn.XLOOKUP($U:$U,$W:$W,0,0) -> #NAME? | S22: MG | T22: MG | U22: 25471574001060 | V22: XZ | W22: MINAS MASTER
A23: B00162 | B23: 66194234000125 | C23: 128316 | D23: 1791 | E23: DROGARIA E DRUGSTORE FERNANDO | F23: 10437 | G23: INDIVIDUAL | H23: 34808 | I23: 19 | J23: 34808 | K23: 7 | L23: B00162 | M23: ATIVO | N23: GABRIEL GONCALVES FONSECA | O23: ANDRE DIAS DE OLIVEIRA | P23: =_xlfn.XLOOKUP('MEDIA TRI'!$E:$E,'MEDIA TRI'!$AA:$AA,"-",0) -> #NAME? | Q23: =_xlfn.XLOOKUP($U:$U,$V:$V,0,0) -> #NAME? | R23: =_xlfn.XLOOKUP($U:$U,$W:$W,0,0) -> #NAME? | S23: MG | T23: MG | U23: 25471574001060 | V23: XZ | W23: MINAS MASTER
A24: B00188 | B24: 1119450000160 | C24: 124189 | D24: 1146 | E24: EFEITTO FCIA E MANIP LT | F24: 10437 | G24: INDIVIDUAL | H24: 30015 | I24: 20 | J24: 30015 | K24: 7 | L24: B00188 | M24: ATIVO | N24: GABRIEL GONCALVES FONSECA | O24: INATIVO - MG3 | P24: =_xlfn.XLOOKUP('MEDIA TRI'!$E:$E,'MEDIA TRI'!$AA:$AA,"-",0) -> #NAME? | Q24: =_xlfn.XLOOKUP($U:$U,$V:$V,0,0) -> #NAME? | R24: =_xlfn.XLOOKUP($U:$U,$W:$W,0,0) -> #NAME? | S24: MG | T24: MGI | U24: 54012406000385 | V24: 1P | W24: MIX FARMA
A25: B00279 | B25: 18806430000160 | C25: 106716 | D25: 333 | E25: DROGARIA USIFARMA LTDA EPP | F25: 10437 | G25: INDIVIDUAL | H25: 35992 | I25: 7 | J25: 35992 | K25: 7 | L25: B00279 | M25: ATIVO | N25: GABRIEL GONCALVES FONSECA | O25: GUSTAVO GONCALVES | P25: =_xlfn.XLOOKUP('MEDIA TRI'!$E:$E,'MEDIA TRI'!$AA:$AA,"-",0) -> #NAME? | Q25: =_xlfn.XLOOKUP($U:$U,$V:$V,0,0) -> #NAME? | R25: =_xlfn.XLOOKUP($U:$U,$W:$W,0,0) -> #NAME? | S25: MG | T25: MG | U25: 54012406000385 | V25: 1P | W25: MIX FARMA
A26: B00287 | B26: 25791013000157 | C26: 114183 | D26: 282 | E26: DROG SAO FELIX LTDA EPP | F26: 10437 | G26: INDIVIDUAL | H26: 35997 | I26: 14 | J26: 35997 | K26: 7 | L26: B26951 | M26: ATIVO | N26: GABRIEL GONCALVES FONSECA | O26: GUSTAVO GONCALVES | P26: =_xlfn.XLOOKUP('MEDIA TRI'!$E:$E,'MEDIA TRI'!$AA:$AA,"-",0) -> #NAME? | Q26: =_xlfn.XLOOKUP($U:$U,$V:$V,0,0) -> #NAME? | R26: =_xlfn.XLOOKUP($U:$U,$W:$W,0,0) -> #NAME? | S26: MG | T26: MG | U26: 2322043000208 | V26: D9 | W26: REDE UNIMED
A27: B00337 | B27: 18366237000156 | C27: 110938 | D27: 1828 | E27: DROGARIA FERRAZ DE RECREIO LT | F27: 14175 | G27: INOVA DROGARIA | H27: 34925 | I27: 56 | J27: 34925 | K27: 7 | L27: B00337 | M27: ATIVO | N27: JULIANO DE MOURA HIDAKA | O27: VAGO - ZONA DA MATA - MG | P27: =_xlfn.XLOOKUP('MEDIA TRI'!$E:$E,'MEDIA TRI'!$AA:$AA,"-",0) -> #NAME? | Q27: =_xlfn.XLOOKUP($U:$U,$V:$V,0,0) -> #NAME? | R27: =_xlfn.XLOOKUP($U:$U,$W:$W,0,0) -> #NAME? | S27: MG | T27: MGI | U27: 2322043000208 | V27: D9 | W27: REDE UNIMED
A28: B00410 | B28: 2806415000182 | C28: 163077 | D28: 3412 | E28: DROGARIA FRAGA & BARROS LTDA | F28: 10437 | G28: INDIVIDUAL | H28: 30015 | I28: 21 | J28: 30015 | K28: 7 | L28: B00410 | M28: ATIVO | N28: JULIANO DE MOURA HIDAKA | O28: INATIVO - MG4 | P28: =_xlfn.XLOOKUP('MEDIA TRI'!$E:$E,'MEDIA TRI'!$AA:$AA,"-",0) -> #NAME? | Q28: =_xlfn.XLOOKUP($U:$U,$V:$V,0,0) -> #NAME? | R28: =_xlfn.XLOOKUP($U:$U,$W:$W,0,0) -> #NAME? | S28: MG | T28: MGI | U28: 45425899000637 | V28: D9 | W28: REDE UNIMED
A29: B00444 | B29: 25178070000165 | C29: 145698 | D29: 346 | E29: DROGARIA VIEIRA E BERNO LTDA | F29: 10437 | G29: INDIVIDUAL | H29: 30015 | I29: 21 | J29: 30015 | K29: 7 | L29: B00444 | M29: ATIVO | N29: GABRIEL GONCALVES FONSECA | O29: ANDRE DIAS DE OLIVEIRA | P29: =_xlfn.XLOOKUP('MEDIA TRI'!$E:$E,'MEDIA TRI'!$AA:$AA,"-",0) -> #NAME? | Q29: =_xlfn.XLOOKUP($U:$U,$V:$V,0,0) -> #NAME? | R29: =_xlfn.XLOOKUP($U:$U,$W:$W,0,0) -> #NAME? | S29: MG | T29: MG | U29: 45425899000637 | V29: D9 | W29: REDE UNIMED
A30: B00477 | B30: 22603286000132 | C30: 113973 | D30: 3503 | E30: DROG CENTRAL DE MONTE CARMELO | F30: 10437 | G30: INDIVIDUAL | H30: 30015 | I30: 21 | J30: 30015 | K30: 7 | L30: B00477 | M30: ATIVO | N30: GABRIEL GONCALVES FONSECA | O30: THIAGO DE CASTRO MARIA | P30: =_xlfn.XLOOKUP('MEDIA TRI'!$E:$E,'MEDIA TRI'!$AA:$AA,"-",0) -> #NAME? | Q30: =_xlfn.XLOOKUP($U:$U,$V:$V,0,0) -> #NAME? | R30: =_xlfn.XLOOKUP($U:$U,$W:$W,0,0) -> #NAME? | S30: MG | T30: MGI | U30: 86483542000340 | V30: 5H | W30: UNIMED MG
A31: B00501 | B31: 19260967000130 | C31: 140153 | D31: 542 | E31: ALVIM E LIMA LTDA | F31: 10437 | G31: INDIVIDUAL | H31: 35181 | I31: 55 | J31: 35181 | K31: 7 | L31: B00501 | M31: ATIVO | N31: JULIANO DE MOURA HIDAKA | O31: VAGO - ZONA DA MATA - MG | P31: =_xlfn.XLOOKUP('MEDIA TRI'!$E:$E,'MEDIA TRI'!$AA:$AA,"-",0) -> #NAME? | Q31: =_xlfn.XLOOKUP($U:$U,$V:$V,0,0) -> #NAME? | R31: =_xlfn.XLOOKUP($U:$U,$W:$W,0,0) -> #NAME? | S31: MG | T31: MGI | U31: 86483542000340 | V31: 5H | W31: UNIMED MG
A32: B00543 | B32: 20295028000100 | C32: 135251 | D32: 1828 | E32: DROGARIA ATLAS LTDA | F32: 10437 | G32: INDIVIDUAL | H32: 30015 | I32: 21 | J32: 30015 | K32: 7 | L32: B00543 | M32: ATIVO | N32: JULIANO DE MOURA HIDAKA | O32: VAGO - ZONA DA MATA - MG | P32: =_xlfn.XLOOKUP('MEDIA TRI'!$E:$E,'MEDIA TRI'!$AA:$AA,"-",0) -> #NAME? | Q32: =_xlfn.XLOOKUP($U:$U,$V:$V,0,0) -> #NAME? | R32: =_xlfn.XLOOKUP($U:$U,$W:$W,0,0) -> #NAME? | S32: MG | T32: MGI | U32: 45399961000310 | V32: SE | W32: REDE UNIMED SOROCABA
A33: B00550 | B33: 17076878000103 | C33: 121980 | D33: 530 | E33: RICCO DROGARIA LTDA | F33: 614 | G33: GRUPOFARMA | H33: 35993 | I33: 35 | J33: 35993 | K33: 7 | L33: B00550 | M33: ATIVO | N33: JULIANO DE MOURA HIDAKA | O33: VAGO - ZONA DA MATA - MG | P33: =_xlfn.XLOOKUP('MEDIA TRI'!$E:$E,'MEDIA TRI'!$AA:$AA,"-",0) -> #NAME? | Q33: =_xlfn.XLOOKUP($U:$U,$V:$V,0,0) -> #NAME? | R33: =_xlfn.XLOOKUP($U:$U,$W:$W,0,0) -> #NAME? | S33: MG | T33: MGI | U33: 45399961000310 | V33: D9 | W33: REDE UNIMED
... A45: B00949 | B45: 21314943000169 | C45: 139512 | D45: 1792 | E45: DROGAFAT LTDA ME | F45: 10437 | G45: INDIVIDUAL | H45: 34808 | I45: 7 | J45: 34808 | K45: 7 | L45: B00949 | M45: ATIVO | N45: JULIANO DE MOURA HIDAKA | O45: VAGO - ZONA DA MATA - MG | P45: =_xlfn.XLOOKUP('MEDIA TRI'!$E:$E,'MEDIA TRI'!$AA:$AA,"-",0) -> #NAME? | Q45: =_xlfn.XLOOKUP($U:$U,$V:$V,0,0) -> #NAME? | R45: =_xlfn.XLOOKUP($U:$U,$W:$W,0,0) -> #NAME? | S45: MG | T45: MG | U45: 89100135000132 | V45: 1P | W45: MIX FARMA
A46: B00972 | B46: 42953463000118 | C46: 146199 | D46: 673 | E46: FARMACIA BITTENCOURT LTDA | F46: 12837 | G46: ENTREFARMA FARMARCAS | H46: 35993 | I46: 14 | J46: 35993 | K46: 7 | L46: B00972 | M46: ATIVO | N46: JULIANO DE MOURA HIDAKA | O46: LUIS CARLOS SILVEIRA | P46: =_xlfn.XLOOKUP('MEDIA TRI'!$E:$E,'MEDIA TRI'!$AA:$AA,"-",0) -> #NAME? | Q46: =_xlfn.XLOOKUP($U:$U,$V:$V,0,0) -> #NAME? | R46: =_xlfn.XLOOKUP($U:$U,$W:$W,0,0) -> #NAME? | S46: MG | T46: MG | U46: 75584193000174 | V46: 29 | W46: INDIVIDUAL
A47: B00998 | B47: 7332186000125 | C47: 119277 | D47: 2252 | E47: DROG E PERF CARBONITA LT | F47: 14175 | G47: INOVA DROGARIA | H47: 34808 | I47: 21 | J47: 34808 | K47: 7 | L47: B00998 | M47: ATIVO | N47: GABRIEL GONCALVES FONSECA | O47: ANDRE DIAS DE OLIVEIRA | P47: =_xlfn.XLOOKUP('MEDIA TRI'!$E:$E,'MEDIA TRI'!$AA:$AA,"-",0) -> #NAME? | Q47: =_xlfn.XLOOKUP($U:$U,$V:$V,0,0) -> #NAME? | R47: =_xlfn.XLOOKUP($U:$U,$W:$W,0,0) -> #NAME? | S47: MG | T47: MG | U47: 75584193000174 | V47: 29 | W47: INDIVIDUAL
A48: B01004 | B48: 20716312000103 | C48: 110855 | D48: 2251 | E48: DROGARIA PIRAUBA LTDA | F48: 10437 | G48: INDIVIDUAL | H48: 35195 | I48: 35 | J48: 35195 | K48: 7 | L48: B01004 | M48: ATIVO | N48: JULIANO DE MOURA HIDAKA | O48: VAGO - ZONA DA MATA - MG | P48: =_xlfn.XLOOKUP('MEDIA TRI'!$E:$E,'MEDIA TRI'!$AA:$AA,"-",0) -> #NAME? | Q48: =_xlfn.XLOOKUP($U:$U,$V:$V,0,0) -> #NAME? | R48: =_xlfn.XLOOKUP($U:$U,$W:$W,0,0) -> #NAME? | S48: MG | T48: MGI | U48: 44863959000207
A49: B01020 | B49: 42811083000149 | C49: 148569 | D49: 598 | E49: DROGARIA FRANERI LTDA | F49: 10437 | G49: INDIVIDUAL | H49: 35993 | I49: 30 | J49: 35993 | K49: 7 | L49: B01020 | M49: ATIVO | N49: GABRIEL GONCALVES FONSECA | O49: CIRO DE CARVALHO MIRANDA | P49: =_xlfn.XLOOKUP('MEDIA TRI'!$E:$E,'MEDIA TRI'!$AA:$AA,"-",0) -> #NAME? | Q49: =_xlfn.XLOOKUP($U:$U,$V:$V,0,0) -> #NAME? | R49: =_xlfn.XLOOKUP($U:$U,$W:$W,0,0) -> #NAME? | S49: MG | T49: MG | U49: 44863959000207
A50: B01061 | B50: 38603999000136 | C50: 127960 | D50: 327 | E50: FARMACIA BOY E ALVES LTDA | F50: 10437 | G50: INDIVIDUAL | H50: 35160 | I50: 7 | J50: 35160 | K50: 7 | L50: B01061 | M50: ATIVO | N50: GABRIEL GONCALVES FONSECA | O50: CIRO DE CARVALHO MIRANDA | P50: =_xlfn.XLOOKUP('MEDIA TRI'!$E:$E,'MEDIA TRI'!$AA:$AA,"-",0) -> #NAME? | Q50: =_xlfn.XLOOKUP($U:$U,$V:$V,0,0) -> #NAME? | R50: =_xlfn.XLOOKUP($U:$U,$W:$W,0,0) -> #NAME? | S50: MG | T50: MG | U50: 65732836000207 | V50: 1P | W50: MIX FARMA
A51: B01103 | B51: 25357922000181 | C51: 105167 | D51: 327 | E51: ALTIVO RICARDO ROCHA | F51: 14175 | G51: INOVA DROGARIA | H51: 35997 | I51: 35 | J51: 35997 | K51: 7 | L51: B01103 | M51: ATIVO | N51: GABRIEL GONCALVES FONSECA | O51: CIRO DE CARVALHO MIRANDA | P51: =_xlfn.XLOOKUP('MEDIA TRI'!$E:$E,'MEDIA TRI'!$AA:$AA,"-",0) -> #NAME? | Q51: =_xlfn.XLOOKUP($U:$U,$V:$V,0,0) -> #NAME? | R51: =_xlfn.XLOOKUP($U:$U,$W:$W,0,0) -> #NAME? | S51: MG | T51: MG | U51: 65732836000207 | V51: 1P | W51: MIX FARMA
A52: B01111 | B52: 21264171000106 | C52: 101066 | D52: 327 | E52: J CORREA DE FARIA E CIA LTDA | F52: 10437 | G52: INDIVIDUAL | H52: 34880 | I52: 21 | J52: 34880 | K52: 7 | L52: B01111 | M52: ATIVO | N52: GABRIEL GONCALVES FONSECA | O52: CIRO DE CARVALHO MIRANDA | P52: =_xlfn.XLOOKUP('MEDIA TRI'!$E:$E,'MEDIA TRI'!$AA:$AA,"-",0) -> #NAME? | Q52: =_xlfn.XLOOKUP($U:$U,$V:$V,0,0) -> #NAME? | R52: =_xlfn.XLOOKUP($U:$U,$W:$W,0,0) -> #NAME? | S52: MG | T52: MGI | U52: 20909271000171 | V52: 29 | W52: INDIVIDUAL
A53: B01160 | B53: 66399924000110 | C53: 112840 | D53: 836 | E53: DROGAEFICAZ LTDA | F53: 11423 | G53: MINASDROGAS | H53: 34925 | I53: 52 | J53: 34925 | K53: 7 | L53: B49896 | M53: ATIVO | N53: GABRIEL GONCALVES FONSECA | O53: GUSTAVO GONCALVES | P53: =_xlfn.XLOOKUP('MEDIA TRI'!$E:$E,'MEDIA TRI'!$AA:$AA,"-",0) -> #NAME? | Q53: =_xlfn.XLOOKUP($U:$U,$V:$V,0,0) -> #NAME? | R53: =_xlfn.XLOOKUP($U:$U,$W:$W,0,0) -> #NAME? | S53: MG | T53: MG | U53: 20909271000171 | V53: 29 | W53: INDIVIDUAL
A54: B01178 | B54: 71337737000142 | C54: 102638 | D54: 388 | E54: JOSIANE MONTEIRO B OLIVEIRA ME | F54: 10437 | G54: INDIVIDUAL | H54: 35999 | I54: 8 | J54: 35999 | K54: 7 | L54: B01178 | M54: ATIVO | N54: GABRIEL GONCALVES FONSECA | O54: CIRO DE CARVALHO MIRANDA | P54: =_xlfn.XLOOKUP('MEDIA TRI'!$E:$E,'MEDIA TRI'!$AA:$AA,"-",0) -> #NAME? | Q54: =_xlfn.XLOOKUP($U:$U,$V:$V,0,0) -> #NAME? | R54: =_xlfn.XLOOKUP($U:$U,$W:$W,0,0) -> #NAME? | S54: MG | T54: MG | U54: 20909271000171 | V54: 5H | W54: UNIMED MG
A55: B01186 | B55: 22147631000170 | C55: 131319 | D55: 1828 | E55: FARMACIA BARBOSA LTDA | F55: 9336 | G55: FECOFAR AMERICANA | H55: 35677 | I55: 35 | J55: 35677 | K55: 7 | L55: B01186 | M55: ATIVO | N55: JULIANO DE MOURA HIDAKA | O55: VAGO - ZONA DA MATA - MG | P55: =_xlfn.XLOOKUP('MEDIA TRI'!$E:$E,'MEDIA TRI'!$AA:$AA,"-",0) -> #NAME? | Q55: =_xlfn.XLOOKUP($U:$U,$V:$V,0,0) -> #NAME? | R55: =_xlfn.XLOOKUP($U:$U,$W:$W,0,0) -> #NAME? | S55: MG | T55: MGI | U55: 50480953000334 | V55: VI | W55: REDE UNIMED LIMEIRA
A56: B01202 | B56: 21673132000154 | C56: 104466 | D56: 363 | E56: DROGARIA GARCIAS LTDA | F56: 14059 | G56: DSG MAIS BRASIL | H56: 35993 | I56: 20 | J56: 35993 | K56: 7 | L56: B01202 | M56: ATIVO | N56: JULIANO DE MOURA HIDAKA | O56: LUIS CARLOS SILVEIRA | P56: =_xlfn.XLOOKUP('MEDIA TRI'!$E:$E,'MEDIA TRI'!$AA:$AA,"-",0) -> #NAME? | Q56: =_xlfn.XLOOKUP($U:$U,$V:$V,0,0) -> #NAME? | R56: =_xlfn.XLOOKUP($U:$U,$W:$W,0,0) -> #NAME? | S56: MG | T56: MG | U56: 50480953000334 | V56: VI | W56: REDE UNIMED LIMEIRA
...

Sheet SOMA
T2: ↓ | U2: ↓
B3: V. 4.0 08/04 | C3: 46120
B4: USAR PONTO ( . ) NAS DATAS | Q4: PREENCHER PARA CADASTRAR SOMA
L5: ↓ | Q5: PROPOSTO | V5: ↓ | W5: ↓ | X5: ↓
B6: PERÍODO NEGOCIAÇÃO INÍCIO | C6: PERÍODO NEGOCIAÇÃO FIM | D6: MARCA SOLICITANTE | E6: FILIAL | F6: GV | G6: SUPERVISOR | H6: ORGANIZAÇÃO DE VENDAS | I6: CÓDIGO SAP CLIENTE | J6: CÓDIGO PFAT CLIENTE | K6: RAZÃO SOCIAL | L6: CÓD. REDE | M6: NOME REDE | N6: CÓD. BAND | O6: NOME BANDEIRA | P6: AÇÃO PARA REDE OU CLIENTE? | Q6: % SOMA TOTAL | R6: % COMERCIAL | S6: % FINANCEIRO | T6: MATERIAL BANDEIRA GMR GERAL | U6: DESCRIÇÃO | V6: MD TRIM | W6: VOLUME PROPOSTO PARA O PERÍODO | X6: OBS
B8: =TODAY() -> 46135 | C8: INDETERMINADO | D8: SANTA CRUZ | E8: =IFERROR(VLOOKUP($J8,'Base 1'!A:S,19,0),"-") -> - | F8: =IFERROR(VLOOKUP($J8,'Base 1'!$A:$N,14,0),"-") -> - | G8: =IFERROR(VLOOKUP($J8,'Base 1'!$A:$O,15,0),"-") -> - | H8: =IFERROR(VLOOKUP($J8,'Base 1'!$A:$T,20,0),"-") -> - | I8: =IFERROR(VLOOKUP($J8,'Base 1'!$A:$C,3,0),"-") -> - | K8: =IFERROR(VLOOKUP($J8,'Base 1'!$A:$E,5,0),"-") -> - | L8: =IFERROR(VLOOKUP($J8,'Base 1'!$A:$Q,17,0),"-") -> - | M8: =IFERROR(VLOOKUP($J8,'Base 1'!$A:$R,18,0),"-") -> - | N8: =IFERROR(VLOOKUP($J8,'Base 1'!$A:$F,6,0),"-") -> - | O8: =IFERROR(VLOOKUP($J8,'Base 1'!$A:$G,7,0),"-") -> - | Q8: - | R8: - | U8: - | V8: =IFERROR(VLOOKUP($J8,'Base 1'!$A:$Q,16,0),"-") -> - | W8: - | X8: -
B9: =TODAY() -> 46135 | C9: INDETERMINADO | D9: SANTA CRUZ | E9: =IFERROR(VLOOKUP($J9,'Base 1'!A:S,19,0),"-") -> - | F9: =IFERROR(VLOOKUP($J9,'Base 1'!$A:$N,14,0),"-") -> - | G9: =IFERROR(VLOOKUP($J9,'Base 1'!$A:$O,15,0),"-") -> - | H9: =IFERROR(VLOOKUP($J9,'Base 1'!$A:$T,20,0),"-") -> - | I9: =IFERROR(VLOOKUP($J9,'Base 1'!$A:$C,3,0),"-") -> - | K9: =IFERROR(VLOOKUP($J9,'Base 1'!$A:$E,5,0),"-") -> - | L9: =IFERROR(VLOOKUP($J9,'Base 1'!$A:$Q,17,0),"-") -> - | M9: =IFERROR(VLOOKUP($J9,'Base 1'!$A:$R,18,0),"-") -> - | N9: =IFERROR(VLOOKUP($J9,'Base 1'!$A:$F,6,0),"-") -> - | O9: =IFERROR(VLOOKUP($J9,'Base 1'!$A:$G,7,0),"-") -> - | Q9: - | R9: - | U9: - | V9: =IFERROR(VLOOKUP($J9,'Base 1'!$A:$Q,16,0),"-") -> - | W9: - | X9: -
B10: =TODAY() -> 46135 | C10: INDETERMINADO | D10: SANTA CRUZ | E10: =IFERROR(VLOOKUP($J10,'Base 1'!A:S,19,0),"-") -> - | F10: =IFERROR(VLOOKUP($J10,'Base 1'!$A:$N,14,0),"-") -> - | G10: =IFERROR(VLOOKUP($J10,'Base 1'!$A:$O,15,0),"-") -> - | H10: =IFERROR(VLOOKUP($J10,'Base 1'!$A:$T,20,0),"-") -> - | I10: =IFERROR(VLOOKUP($J10,'Base 1'!$A:$C,3,0),"-") -> - | K10: =IFERROR(VLOOKUP($J10,'Base 1'!$A:$E,5,0),"-") -> - | L10: =IFERROR(VLOOKUP($J10,'Base 1'!$A:$Q,17,0),"-") -> - | M10: =IFERROR(VLOOKUP($J10,'Base 1'!$A:$R,18,0),"-") -> - | N10: =IFERROR(VLOOKUP($J10,'Base 1'!$A:$F,6,0),"-") -> - | O10: =IFERROR(VLOOKUP($J10,'Base 1'!$A:$G,7,0),"-") -> - | Q10: - | R10: - | U10: - | V10: =IFERROR(VLOOKUP($J10,'Base 1'!$A:$Q,16,0),"-") -> - | W10: - | X10: -
B11: =TODAY() -> 46135 | C11: INDETERMINADO | D11: SANTA CRUZ | E11: =IFERROR(VLOOKUP($J11,'Base 1'!A:S,19,0),"-") -> - | F11: =IFERROR(VLOOKUP($J11,'Base 1'!$A:$N,14,0),"-") -> - | G11: =IFERROR(VLOOKUP($J11,'Base 1'!$A:$O,15,0),"-") -> - | H11: =IFERROR(VLOOKUP($J11,'Base 1'!$A:$T,20,0),"-") -> - | I11: =IFERROR(VLOOKUP($J11,'Base 1'!$A:$C,3,0),"-") -> - | K11: =IFERROR(VLOOKUP($J11,'Base 1'!$A:$E,5,0),"-") -> - | L11: =IFERROR(VLOOKUP($J11,'Base 1'!$A:$Q,17,0),"-") -> - | M11: =IFERROR(VLOOKUP($J11,'Base 1'!$A:$R,18,0),"-") -> - | N11: =IFERROR(VLOOKUP($J11,'Base 1'!$A:$F,6,0),"-") -> - | O11: =IFERROR(VLOOKUP($J11,'Base 1'!$A:$G,7,0),"-") -> - | Q11: - | R11: - | U11: - | V11: =IFERROR(VLOOKUP($J11,'Base 1'!$A:$Q,16,0),"-") -> - | W11: - | X11: -
B12: =TODAY() -> 46135 | C12: INDETERMINADO | D12: SANTA CRUZ | E12: =IFERROR(VLOOKUP($J12,'Base 1'!A:S,19,0),"-") -> - | F12: =IFERROR(VLOOKUP($J12,'Base 1'!$A:$N,14,0),"-") -> - | G12: =IFERROR(VLOOKUP($J12,'Base 1'!$A:$O,15,0),"-") -> - | H12: =IFERROR(VLOOKUP($J12,'Base 1'!$A:$T,20,0),"-") -> - | I12: =IFERROR(VLOOKUP($J12,'Base 1'!$A:$C,3,0),"-") -> - | K12: =IFERROR(VLOOKUP($J12,'Base 1'!$A:$E,5,0),"-") -> - | L12: =IFERROR(VLOOKUP($J12,'Base 1'!$A:$Q,17,0),"-") -> - | M12: =IFERROR(VLOOKUP($J12,'Base 1'!$A:$R,18,0),"-") -> - | N12: =IFERROR(VLOOKUP($J12,'Base 1'!$A:$F,6,0),"-") -> - | O12: =IFERROR(VLOOKUP($J12,'Base 1'!$A:$G,7,0),"-") -> - | Q12: - | R12: - | U12: - | V12: =IFERROR(VLOOKUP($J12,'Base 1'!$A:$Q,16,0),"-") -> - | W12: - | X12: -
